[2022-04-18 20:07:23,137] ERROR in app: Exception on / [GET]
Traceback (most recent call last):
  File "C:\Users\CDL-Segun\Documents\Projects\CDL\CDL_ScanAudit\ScanAudit\lib\site-packages\flask\app.py", line 2073, in wsgi_app
    response = self.full_dispatch_request()
  File "C:\Users\CDL-Segun\Documents\Projects\CDL\CDL_ScanAudit\ScanAudit\lib\site-packages\flask\app.py", line 1518, in full_dispatch_request
    rv = self.handle_user_exception(e)
  File "C:\Users\CDL-Segun\Documents\Projects\CDL\CDL_ScanAudit\ScanAudit\lib\site-packages\flask\app.py", line 1516, in full_dispatch_request
    rv = self.dispatch_request()
  File "C:\Users\CDL-Segun\Documents\Projects\CDL\CDL_ScanAudit\ScanAudit\lib\site-packages\flask\app.py", line 1502, in dispatch_request
    return self.ensure_sync(self.view_functions[rule.endpoint])(**req.view_args)
  File "C:\Users\CDL-Segun\Documents\Projects\CDL\CDL_ScanAudit\main.py", line 115, in test_route
    generate_scan_file_list(last_audit)
  File "C:\Users\CDL-Segun\Documents\Projects\CDL\CDL_ScanAudit\main.py", line 103, in generate_scan_file_list
    if last_audit is not None and modified <= last_audit:
TypeError: can't compare offset-naive and offset-aware datetimes
[2022-04-18 21:07:11,551] ERROR in app: Exception on / [GET]
Traceback (most recent call last):
  File "C:\Users\CDL-Segun\Documents\Projects\CDL\CDL_ScanAudit\ScanAudit\lib\site-packages\flask\app.py", line 2073, in wsgi_app
    response = self.full_dispatch_request()
  File "C:\Users\CDL-Segun\Documents\Projects\CDL\CDL_ScanAudit\ScanAudit\lib\site-packages\flask\app.py", line 1518, in full_dispatch_request
    rv = self.handle_user_exception(e)
  File "C:\Users\CDL-Segun\Documents\Projects\CDL\CDL_ScanAudit\ScanAudit\lib\site-packages\flask\app.py", line 1516, in full_dispatch_request
    rv = self.dispatch_request()
  File "C:\Users\CDL-Segun\Documents\Projects\CDL\CDL_ScanAudit\ScanAudit\lib\site-packages\flask\app.py", line 1502, in dispatch_request
    return self.ensure_sync(self.view_functions[rule.endpoint])(**req.view_args)
  File "C:\Users\CDL-Segun\Documents\Projects\CDL\CDL_ScanAudit\main.py", line 143, in test_route
    unscanned_codes = get_unscanned_codes(scan_codes)
  File "C:\Users\CDL-Segun\Documents\Projects\CDL\CDL_ScanAudit\main.py", line 124, in get_unscanned_codes
    db_scan_codes = session.query(OrderScans.SCANCode).all()
AttributeError: type object 'OrderScans' has no attribute 'SCANCode'
[2022-04-18 21:09:11,628] ERROR in app: Exception on / [GET]
Traceback (most recent call last):
  File "C:\Users\CDL-Segun\Documents\Projects\CDL\CDL_ScanAudit\ScanAudit\lib\site-packages\flask\app.py", line 2073, in wsgi_app
    response = self.full_dispatch_request()
  File "C:\Users\CDL-Segun\Documents\Projects\CDL\CDL_ScanAudit\ScanAudit\lib\site-packages\flask\app.py", line 1518, in full_dispatch_request
    rv = self.handle_user_exception(e)
  File "C:\Users\CDL-Segun\Documents\Projects\CDL\CDL_ScanAudit\ScanAudit\lib\site-packages\flask\app.py", line 1516, in full_dispatch_request
    rv = self.dispatch_request()
  File "C:\Users\CDL-Segun\Documents\Projects\CDL\CDL_ScanAudit\ScanAudit\lib\site-packages\flask\app.py", line 1502, in dispatch_request
    return self.ensure_sync(self.view_functions[rule.endpoint])(**req.view_args)
  File "C:\Users\CDL-Segun\Documents\Projects\CDL\CDL_ScanAudit\main.py", line 143, in test_route
    unscanned_codes = get_unscanned_codes(scan_codes)
  File "C:\Users\CDL-Segun\Documents\Projects\CDL\CDL_ScanAudit\main.py", line 124, in get_unscanned_codes
    db_scan_codes = session.query(OrderScans.SCANCode).all()
AttributeError: type object 'OrderScans' has no attribute 'SCANCode'
[2022-04-18 21:10:45,785] ERROR in app: Exception on / [GET]
Traceback (most recent call last):
  File "C:\Users\CDL-Segun\Documents\Projects\CDL\CDL_ScanAudit\ScanAudit\lib\site-packages\flask\app.py", line 2073, in wsgi_app
    response = self.full_dispatch_request()
  File "C:\Users\CDL-Segun\Documents\Projects\CDL\CDL_ScanAudit\ScanAudit\lib\site-packages\flask\app.py", line 1518, in full_dispatch_request
    rv = self.handle_user_exception(e)
  File "C:\Users\CDL-Segun\Documents\Projects\CDL\CDL_ScanAudit\ScanAudit\lib\site-packages\flask\app.py", line 1516, in full_dispatch_request
    rv = self.dispatch_request()
  File "C:\Users\CDL-Segun\Documents\Projects\CDL\CDL_ScanAudit\ScanAudit\lib\site-packages\flask\app.py", line 1502, in dispatch_request
    return self.ensure_sync(self.view_functions[rule.endpoint])(**req.view_args)
  File "C:\Users\CDL-Segun\Documents\Projects\CDL\CDL_ScanAudit\main.py", line 143, in test_route
    unscanned_codes = get_unscanned_codes(scan_codes)
  File "C:\Users\CDL-Segun\Documents\Projects\CDL\CDL_ScanAudit\main.py", line 131, in get_unscanned_codes
    unscanned_codes = list(set(scan_codes) - set(db_scan_codes))
TypeError: unhashable type: 'dict'
[2022-04-18 21:13:52,610] ERROR in app: Exception on / [GET]
Traceback (most recent call last):
  File "C:\Users\CDL-Segun\Documents\Projects\CDL\CDL_ScanAudit\ScanAudit\lib\site-packages\flask\app.py", line 2073, in wsgi_app
    response = self.full_dispatch_request()
  File "C:\Users\CDL-Segun\Documents\Projects\CDL\CDL_ScanAudit\ScanAudit\lib\site-packages\flask\app.py", line 1518, in full_dispatch_request
    rv = self.handle_user_exception(e)
  File "C:\Users\CDL-Segun\Documents\Projects\CDL\CDL_ScanAudit\ScanAudit\lib\site-packages\flask\app.py", line 1516, in full_dispatch_request
    rv = self.dispatch_request()
  File "C:\Users\CDL-Segun\Documents\Projects\CDL\CDL_ScanAudit\ScanAudit\lib\site-packages\flask\app.py", line 1502, in dispatch_request
    return self.ensure_sync(self.view_functions[rule.endpoint])(**req.view_args)
  File "C:\Users\CDL-Segun\Documents\Projects\CDL\CDL_ScanAudit\main.py", line 143, in test_route
    unscanned_codes = get_unscanned_codes(scan_codes)
  File "C:\Users\CDL-Segun\Documents\Projects\CDL\CDL_ScanAudit\main.py", line 131, in get_unscanned_codes
    unscanned_codes = list(set(scan_codes) - set(db_scan_codes))
TypeError: unhashable type: 'dict'
[2022-04-18 22:12:38,123] ERROR in app: Exception on / [GET]
Traceback (most recent call last):
  File "C:\Users\CDL-Segun\Documents\Projects\CDL\CDL_ScanAudit\ScanAudit\lib\site-packages\flask\app.py", line 2073, in wsgi_app
    response = self.full_dispatch_request()
  File "C:\Users\CDL-Segun\Documents\Projects\CDL\CDL_ScanAudit\ScanAudit\lib\site-packages\flask\app.py", line 1518, in full_dispatch_request
    rv = self.handle_user_exception(e)
  File "C:\Users\CDL-Segun\Documents\Projects\CDL\CDL_ScanAudit\ScanAudit\lib\site-packages\flask\app.py", line 1516, in full_dispatch_request
    rv = self.dispatch_request()
  File "C:\Users\CDL-Segun\Documents\Projects\CDL\CDL_ScanAudit\ScanAudit\lib\site-packages\flask\app.py", line 1502, in dispatch_request
    return self.ensure_sync(self.view_functions[rule.endpoint])(**req.view_args)
  File "C:\Users\CDL-Segun\Documents\Projects\CDL\CDL_ScanAudit\main.py", line 191, in test_route
    audit_report = generate_audit_report(scan_codes, unscanned_orders)
  File "C:\Users\CDL-Segun\Documents\Projects\CDL\CDL_ScanAudit\main.py", line 171, in generate_audit_report
    if unscanned_orders[scan] is not None:
KeyError: 'AECDL10862793'
[2022-04-18 22:16:16,119] ERROR in app: Exception on / [GET]
Traceback (most recent call last):
  File "C:\Users\CDL-Segun\Documents\Projects\CDL\CDL_ScanAudit\ScanAudit\lib\site-packages\flask\app.py", line 2073, in wsgi_app
    response = self.full_dispatch_request()
  File "C:\Users\CDL-Segun\Documents\Projects\CDL\CDL_ScanAudit\ScanAudit\lib\site-packages\flask\app.py", line 1518, in full_dispatch_request
    rv = self.handle_user_exception(e)
  File "C:\Users\CDL-Segun\Documents\Projects\CDL\CDL_ScanAudit\ScanAudit\lib\site-packages\flask\app.py", line 1516, in full_dispatch_request
    rv = self.dispatch_request()
  File "C:\Users\CDL-Segun\Documents\Projects\CDL\CDL_ScanAudit\ScanAudit\lib\site-packages\flask\app.py", line 1502, in dispatch_request
    return self.ensure_sync(self.view_functions[rule.endpoint])(**req.view_args)
  File "C:\Users\CDL-Segun\Documents\Projects\CDL\CDL_ScanAudit\main.py", line 191, in test_route
    audit_report = generate_audit_report(scan_codes, unscanned_orders)
  File "C:\Users\CDL-Segun\Documents\Projects\CDL\CDL_ScanAudit\main.py", line 171, in generate_audit_report
    if unscanned_orders.has_key(scan):
AttributeError: 'dict' object has no attribute 'has_key'
[2022-04-18 22:25:04,739] ERROR in app: Exception on / [GET]
Traceback (most recent call last):
  File "C:\Users\CDL-Segun\Documents\Projects\CDL\CDL_ScanAudit\ScanAudit\lib\site-packages\flask\app.py", line 2073, in wsgi_app
    response = self.full_dispatch_request()
  File "C:\Users\CDL-Segun\Documents\Projects\CDL\CDL_ScanAudit\ScanAudit\lib\site-packages\flask\app.py", line 1518, in full_dispatch_request
    rv = self.handle_user_exception(e)
  File "C:\Users\CDL-Segun\Documents\Projects\CDL\CDL_ScanAudit\ScanAudit\lib\site-packages\flask\app.py", line 1516, in full_dispatch_request
    rv = self.dispatch_request()
  File "C:\Users\CDL-Segun\Documents\Projects\CDL\CDL_ScanAudit\ScanAudit\lib\site-packages\flask\app.py", line 1502, in dispatch_request
    return self.ensure_sync(self.view_functions[rule.endpoint])(**req.view_args)
  File "C:\Users\CDL-Segun\Documents\Projects\CDL\CDL_ScanAudit\main.py", line 191, in test_route
    audit_report = generate_audit_report(scan_codes, unscanned_orders)
  File "C:\Users\CDL-Segun\Documents\Projects\CDL\CDL_ScanAudit\main.py", line 174, in generate_audit_report
    worksheet.write('None', 0, unscanned_orders[scan])
KeyError: 'AECDL10862793'
[2022-04-18 22:26:40,019] ERROR in app: Exception on / [GET]
Traceback (most recent call last):
  File "C:\Users\CDL-Segun\Documents\Projects\CDL\CDL_ScanAudit\ScanAudit\lib\site-packages\xlsxwriter\worksheet.py", line 79, in cell_wrapper
    int(first_arg)
ValueError: invalid literal for int() with base 10: 'None'

During handling of the above exception, another exception occurred:

Traceback (most recent call last):
  File "C:\Users\CDL-Segun\Documents\Projects\CDL\CDL_ScanAudit\ScanAudit\lib\site-packages\flask\app.py", line 2073, in wsgi_app
    response = self.full_dispatch_request()
  File "C:\Users\CDL-Segun\Documents\Projects\CDL\CDL_ScanAudit\ScanAudit\lib\site-packages\flask\app.py", line 1518, in full_dispatch_request
    rv = self.handle_user_exception(e)
  File "C:\Users\CDL-Segun\Documents\Projects\CDL\CDL_ScanAudit\ScanAudit\lib\site-packages\flask\app.py", line 1516, in full_dispatch_request
    rv = self.dispatch_request()
  File "C:\Users\CDL-Segun\Documents\Projects\CDL\CDL_ScanAudit\ScanAudit\lib\site-packages\flask\app.py", line 1502, in dispatch_request
    return self.ensure_sync(self.view_functions[rule.endpoint])(**req.view_args)
  File "C:\Users\CDL-Segun\Documents\Projects\CDL\CDL_ScanAudit\main.py", line 191, in test_route
    audit_report = generate_audit_report(scan_codes, unscanned_orders)
  File "C:\Users\CDL-Segun\Documents\Projects\CDL\CDL_ScanAudit\main.py", line 174, in generate_audit_report
    worksheet.write('None', 0, scan_codes[scan])
  File "C:\Users\CDL-Segun\Documents\Projects\CDL\CDL_ScanAudit\ScanAudit\lib\site-packages\xlsxwriter\worksheet.py", line 82, in cell_wrapper
    new_args = xl_cell_to_rowcol(first_arg)
  File "C:\Users\CDL-Segun\Documents\Projects\CDL\CDL_ScanAudit\ScanAudit\lib\site-packages\xlsxwriter\utility.py", line 126, in xl_cell_to_rowcol
    col_str = match.group(2)
AttributeError: 'NoneType' object has no attribute 'group'
[2022-04-18 23:06:27,001] ERROR in app: Exception on /report [POST]
Traceback (most recent call last):
  File "C:\Users\CDL-Segun\Documents\Projects\CDL\CDL_ScanAudit\ScanAudit\lib\site-packages\flask\app.py", line 2073, in wsgi_app
    response = self.full_dispatch_request()
  File "C:\Users\CDL-Segun\Documents\Projects\CDL\CDL_ScanAudit\ScanAudit\lib\site-packages\flask\app.py", line 1518, in full_dispatch_request
    rv = self.handle_user_exception(e)
  File "C:\Users\CDL-Segun\Documents\Projects\CDL\CDL_ScanAudit\ScanAudit\lib\site-packages\flask\app.py", line 1516, in full_dispatch_request
    rv = self.dispatch_request()
  File "C:\Users\CDL-Segun\Documents\Projects\CDL\CDL_ScanAudit\ScanAudit\lib\site-packages\flask\app.py", line 1502, in dispatch_request
    return self.ensure_sync(self.view_functions[rule.endpoint])(**req.view_args)
  File "C:\Users\CDL-Segun\Documents\Projects\CDL\CDL_ScanAudit\main.py", line 210, in report_rte
    return generate_audit_report(scan_codes, unscanned_orders)
  File "C:\Users\CDL-Segun\Documents\Projects\CDL\CDL_ScanAudit\main.py", line 184, in generate_audit_report
    f.write(datetime.now())
TypeError: write() argument must be str, not datetime.datetime
